Traceback (most recent call last):
  File "/usr/local/lib/python3.9/site-packages/jupyter_cache/executors/utils.py", line 51, in single_nb_execution
    executenb(
  File "/usr/local/lib/python3.9/site-packages/nbclient/client.py", line 1087, in execute
    return NotebookClient(nb=nb, resources=resources, km=km, **kwargs).execute()
  File "/usr/local/lib/python3.9/site-packages/nbclient/util.py", line 74, in wrapped
    return just_run(coro(*args, **kwargs))
  File "/usr/local/lib/python3.9/site-packages/nbclient/util.py", line 53, in just_run
    return loop.run_until_complete(coro)
  File "/usr/local/Cellar/python@3.9/3.9.5/Frameworks/Python.framework/Versions/3.9/lib/python3.9/asyncio/base_events.py", line 642, in run_until_complete
    return future.result()
  File "/usr/local/lib/python3.9/site-packages/nbclient/client.py", line 540, in async_execute
    await self.async_execute_cell(
  File "/usr/local/lib/python3.9/site-packages/nbclient/client.py", line 832, in async_execute_cell
    self._check_raise_for_error(cell, exec_reply)
  File "/usr/local/lib/python3.9/site-packages/nbclient/client.py", line 740, in _check_raise_for_error
    raise CellExecutionError.from_cell_and_msg(cell, exec_reply['content'])
nbclient.exceptions.CellExecutionError: An error occurred while executing the following cell:
------------------
%%nwdiag --outfile demo1.svg
  network dmz {
      address = "210.x.x.x/24"

      web01 [address = "210.x.x.1"];
      web02 [address = "210.x.x.2"];
  }
  network internal {
      address = "172.x.x.x/24";

      web01 [address = "172.x.x.1"];
      db01;
      app01;
  }
------------------

[0;31m---------------------------------------------------------------------------[0m
[0;31mFileNotFoundError[0m                         Traceback (most recent call last)
[0;32m/usr/local/lib/python3.9/site-packages/blockdiag_magic/blockdiag.py[0m in [0;36mdiag[0;34m(self, line, cell, command, outfile)[0m
[1;32m    106[0m             [0;31m#file_name = diag_name + '.' + self._publish_mode[0m[0;34m[0m[0;34m[0m[0;34m[0m[0m
[0;32m--> 107[0;31m             [0;32mwith[0m [0mio[0m[0;34m.[0m[0mopen[0m[0;34m([0m[0mdraw_name[0m[0;34m,[0m [0;34m'rb'[0m[0;34m)[0m [0;32mas[0m [0mf[0m[0;34m:[0m[0;34m[0m[0;34m[0m[0m
[0m[1;32m    108[0m                 [0mdata[0m [0;34m=[0m [0mf[0m[0;34m.[0m[0mread[0m[0;34m([0m[0;34m)[0m[0;34m[0m[0;34m[0m[0m

[0;31mFileNotFoundError[0m: [Errno 2] No such file or directory: '/var/folders/l8/qg6m44156_l6bzv_cbkk7bf00000gn/T/tmpsvsgxw1e/tmpke05928w.svg'

During handling of the above exception, another exception occurred:

[0;31mFileNotFoundError[0m                         Traceback (most recent call last)
[0;32m<ipython-input-4-c11343990708>[0m in [0;36m<module>[0;34m[0m
[0;32m----> 1[0;31m [0mget_ipython[0m[0;34m([0m[0;34m)[0m[0;34m.[0m[0mrun_cell_magic[0m[0;34m([0m[0;34m'nwdiag'[0m[0;34m,[0m [0;34m'--outfile demo1.svg'[0m[0;34m,[0m [0;34m'  network dmz {\n      address = "210.x.x.x/24"\n\n      web01 [address = "210.x.x.1"];\n      web02 [address = "210.x.x.2"];\n  }\n  network internal {\n      address = "172.x.x.x/24";\n\n      web01 [address = "172.x.x.1"];\n      db01;\n      app01;\n  }\n'[0m[0;34m)[0m[0;34m[0m[0;34m[0m[0m
[0m
[0;32m/usr/local/lib/python3.9/site-packages/IPython/core/interactiveshell.py[0m in [0;36mrun_cell_magic[0;34m(self, magic_name, line, cell)[0m
[1;32m   2380[0m             [0;32mwith[0m [0mself[0m[0;34m.[0m[0mbuiltin_trap[0m[0;34m:[0m[0;34m[0m[0;34m[0m[0m
[1;32m   2381[0m                 [0margs[0m [0;34m=[0m [0;34m([0m[0mmagic_arg_s[0m[0;34m,[0m [0mcell[0m[0;34m)[0m[0;34m[0m[0;34m[0m[0m
[0;32m-> 2382[0;31m                 [0mresult[0m [0;34m=[0m [0mfn[0m[0;34m([0m[0;34m*[0m[0margs[0m[0;34m,[0m [0;34m**[0m[0mkwargs[0m[0;34m)[0m[0;34m[0m[0;34m[0m[0m
[0m[1;32m   2383[0m             [0;32mreturn[0m [0mresult[0m[0;34m[0m[0;34m[0m[0m
[1;32m   2384[0m [0;34m[0m[0m

[0;32m<decorator-gen-158>[0m in [0;36mnwdiag[0;34m(self, line, cell)[0m

[0;32m/usr/local/lib/python3.9/site-packages/IPython/core/magic.py[0m in [0;36m<lambda>[0;34m(f, *a, **k)[0m
[1;32m    185[0m     [0;31m# but it's overkill for just that one bit of state.[0m[0;34m[0m[0;34m[0m[0;34m[0m[0m
[1;32m    186[0m     [0;32mdef[0m [0mmagic_deco[0m[0;34m([0m[0marg[0m[0;34m)[0m[0;34m:[0m[0;34m[0m[0;34m[0m[0m
[0;32m--> 187[0;31m         [0mcall[0m [0;34m=[0m [0;32mlambda[0m [0mf[0m[0;34m,[0m [0;34m*[0m[0ma[0m[0;34m,[0m [0;34m**[0m[0mk[0m[0;34m:[0m [0mf[0m[0;34m([0m[0;34m*[0m[0ma[0m[0;34m,[0m [0;34m**[0m[0mk[0m[0;34m)[0m[0;34m[0m[0;34m[0m[0m
[0m[1;32m    188[0m [0;34m[0m[0m
[1;32m    189[0m         [0;32mif[0m [0mcallable[0m[0;34m([0m[0marg[0m[0;34m)[0m[0;34m:[0m[0;34m[0m[0;34m[0m[0m

[0;32m/usr/local/lib/python3.9/site-packages/blockdiag_magic/blockdiag.py[0m in [0;36mnwdiag[0;34m(self, line, cell)[0m
[1;32m    150[0m         [0;32mimport[0m [0mnwdiag[0m[0;34m.[0m[0mcommand[0m[0;34m[0m[0;34m[0m[0m
[1;32m    151[0m         [0margs[0m [0;34m=[0m [0mparse_argstring[0m[0;34m([0m[0mself[0m[0;34m.[0m[0mnwdiag[0m[0;34m,[0m [0mline[0m[0;34m)[0m[0;34m[0m[0;34m[0m[0m
[0;32m--> 152[0;31m         [0mself[0m[0;34m.[0m[0mdiag[0m[0;34m([0m[0mline[0m[0;34m,[0m [0;34mf'nwdiag {cell}'[0m[0;34m,[0m [0mnwdiag[0m[0;34m.[0m[0mcommand[0m[0;34m,[0m  [0margs[0m[0;34m.[0m[0moutfile[0m[0;34m)[0m[0;34m[0m[0;34m[0m[0m
[0m[1;32m    153[0m [0;34m[0m[0m
[1;32m    154[0m     [0;34m@[0m[0mcell_magic[0m[0;34m[0m[0;34m[0m[0m

[0;32m/usr/local/lib/python3.9/site-packages/blockdiag_magic/blockdiag.py[0m in [0;36mdiag[0;34m(self, line, cell, command, outfile)[0m
[1;32m    111[0m         [0;32mfinally[0m[0;34m:[0m[0;34m[0m[0;34m[0m[0m
[1;32m    112[0m             [0;32mif[0m [0moutfile[0m[0;34m:[0m[0;34m[0m[0;34m[0m[0m
[0;32m--> 113[0;31m                 [0mcopyfile[0m[0;34m([0m[0mdraw_name[0m[0;34m,[0m [0moutfile[0m[0;34m)[0m[0;34m[0m[0;34m[0m[0m
[0m[1;32m    114[0m             [0;32mfor[0m [0mfile[0m [0;32min[0m [0mos[0m[0;34m.[0m[0mlistdir[0m[0;34m([0m[0mtmpdir[0m[0;34m)[0m[0;34m:[0m[0;34m[0m[0;34m[0m[0m
[1;32m    115[0m                 [0mos[0m[0;34m.[0m[0munlink[0m[0;34m([0m[0mtmpdir[0m [0;34m+[0m [0;34m"/"[0m [0;34m+[0m [0mfile[0m[0;34m)[0m[0;34m[0m[0;34m[0m[0m

[0;32m/usr/local/Cellar/python@3.9/3.9.5/Frameworks/Python.framework/Versions/3.9/lib/python3.9/shutil.py[0m in [0;36mcopyfile[0;34m(src, dst, follow_symlinks)[0m
[1;32m    262[0m         [0mos[0m[0;34m.[0m[0msymlink[0m[0;34m([0m[0mos[0m[0;34m.[0m[0mreadlink[0m[0;34m([0m[0msrc[0m[0;34m)[0m[0;34m,[0m [0mdst[0m[0;34m)[0m[0;34m[0m[0;34m[0m[0m
[1;32m    263[0m     [0;32melse[0m[0;34m:[0m[0;34m[0m[0;34m[0m[0m
[0;32m--> 264[0;31m         [0;32mwith[0m [0mopen[0m[0;34m([0m[0msrc[0m[0;34m,[0m [0;34m'rb'[0m[0;34m)[0m [0;32mas[0m [0mfsrc[0m[0;34m,[0m [0mopen[0m[0;34m([0m[0mdst[0m[0;34m,[0m [0;34m'wb'[0m[0;34m)[0m [0;32mas[0m [0mfdst[0m[0;34m:[0m[0;34m[0m[0;34m[0m[0m
[0m[1;32m    265[0m             [0;31m# macOS[0m[0;34m[0m[0;34m[0m[0;34m[0m[0m
[1;32m    266[0m             [0;32mif[0m [0m_HAS_FCOPYFILE[0m[0;34m:[0m[0;34m[0m[0;34m[0m[0m

[0;31mFileNotFoundError[0m: [Errno 2] No such file or directory: '/var/folders/l8/qg6m44156_l6bzv_cbkk7bf00000gn/T/tmpsvsgxw1e/tmpke05928w.svg'
FileNotFoundError: [Errno 2] No such file or directory: '/var/folders/l8/qg6m44156_l6bzv_cbkk7bf00000gn/T/tmpsvsgxw1e/tmpke05928w.svg'

